2019-07-24 14:10:57,421 ERROR: Exception on / [GET] [in C:\Flask\venv\lib\site-packages\flask\app.py:1891]
Traceback (most recent call last):
  File "C:\Flask\venv\lib\site-packages\flask\app.py", line 2446, in wsgi_app
    response = self.full_dispatch_request()
  File "C:\Flask\venv\lib\site-packages\flask\app.py", line 1951, in full_dispatch_request
    rv = self.handle_user_exception(e)
  File "C:\Flask\venv\lib\site-packages\flask\app.py", line 1820, in handle_user_exception
    reraise(exc_type, exc_value, tb)
  File "C:\Flask\venv\lib\site-packages\flask\_compat.py", line 39, in reraise
    raise value
  File "C:\Flask\venv\lib\site-packages\flask\app.py", line 1949, in full_dispatch_request
    rv = self.dispatch_request()
  File "C:\Flask\venv\lib\site-packages\flask\app.py", line 1935, in dispatch_request
    return self.view_functions[rule.endpoint](**req.view_args)
  File "C:\Flask\venv\lib\site-packages\flask_login\utils.py", line 261, in decorated_view
    return func(*args, **kwargs)
  File "C:\Flask\app\main\routes.py", line 40, in index
    return render_template('index.html', title='ึ๗าณ', form=form, posts=posts.items, next_url=next_url, prev_url=prev_url)
  File "C:\Flask\venv\lib\site-packages\flask\templating.py", line 140, in render_template
    ctx.app,
  File "C:\Flask\venv\lib\site-packages\flask\templating.py", line 120, in _render
    rv = template.render(context)
  File "C:\Flask\venv\lib\site-packages\jinja2\asyncsupport.py", line 76, in render
    return original_render(self, *args, **kwargs)
  File "C:\Flask\venv\lib\site-packages\jinja2\environment.py", line 1008, in render
    return self.environment.handle_exception(exc_info, True)
  File "C:\Flask\venv\lib\site-packages\jinja2\environment.py", line 780, in handle_exception
    reraise(exc_type, exc_value, tb)
  File "C:\Flask\venv\lib\site-packages\jinja2\_compat.py", line 37, in reraise
    raise value.with_traceback(tb)
  File "C:\Flask\app\templates\index.html", line 2, in top-level template code
    {% import 'bootstrap/wtf.html' as wtf %}
  File "C:\Flask\app\templates\base.html", line 1, in top-level template code
    {% extends 'bootstrap/base.html' %}
  File "C:\Flask\venv\lib\site-packages\flask_bootstrap\templates\bootstrap\base.html", line 1, in top-level template code
    {% block doc -%}
  File "C:\Flask\venv\lib\site-packages\flask_bootstrap\templates\bootstrap\base.html", line 4, in block "doc"
    {%- block html %}
  File "C:\Flask\venv\lib\site-packages\flask_bootstrap\templates\bootstrap\base.html", line 20, in block "html"
    {% block body -%}
  File "C:\Flask\venv\lib\site-packages\flask_bootstrap\templates\bootstrap\base.html", line 23, in block "body"
    {% block content -%}
  File "C:\Flask\app\templates\base.html", line 50, in block "content"
    {% block app_content %}{% endblock %}
  File "C:\Flask\app\templates\index.html", line 12, in block "app_content"
    {% include '_post.html' %}
  File "C:\Flask\app\templates\_post.html", line 22, in top-level template code
    <a href="{{ url_for('user', username=post.author.username) }}">
  File "C:\Flask\venv\lib\site-packages\flask\helpers.py", line 370, in url_for
    return appctx.app.handle_url_build_error(error, endpoint, values)
  File "C:\Flask\venv\lib\site-packages\flask\app.py", line 2215, in handle_url_build_error
    reraise(exc_type, exc_value, tb)
  File "C:\Flask\venv\lib\site-packages\flask\_compat.py", line 39, in reraise
    raise value
  File "C:\Flask\venv\lib\site-packages\flask\helpers.py", line 358, in url_for
    endpoint, values, method=method, force_external=external
  File "C:\Flask\venv\lib\site-packages\werkzeug\routing.py", line 2007, in build
    raise BuildError(endpoint, values, method, self)
werkzeug.routing.BuildError: Could not build url for endpoint 'user' with values ['username']. Did you mean 'main.user' instead?
2019-07-24 14:13:21,493 INFO: Microblog startup [in C:\Flask\app\__init__.py:85]
2019-07-24 14:13:23,459 ERROR: Exception on / [GET] [in C:\Flask\venv\lib\site-packages\flask\app.py:1891]
Traceback (most recent call last):
  File "C:\Flask\venv\lib\site-packages\flask\app.py", line 2446, in wsgi_app
    response = self.full_dispatch_request()
  File "C:\Flask\venv\lib\site-packages\flask\app.py", line 1951, in full_dispatch_request
    rv = self.handle_user_exception(e)
  File "C:\Flask\venv\lib\site-packages\flask\app.py", line 1820, in handle_user_exception
    reraise(exc_type, exc_value, tb)
  File "C:\Flask\venv\lib\site-packages\flask\_compat.py", line 39, in reraise
    raise value
  File "C:\Flask\venv\lib\site-packages\flask\app.py", line 1947, in full_dispatch_request
    rv = self.preprocess_request()
  File "C:\Flask\venv\lib\site-packages\flask\app.py", line 2241, in preprocess_request
    rv = func()
  File "C:\Flask\app\main\routes.py", line 17, in before_request
    g.locale = 'zh_CN' if str(get_locale()).startswith('zh') else str(get_locale())
  File "C:\Flask\venv\lib\site-packages\flask_babel\__init__.py", line 257, in get_locale
    rv = babel.locale_selector_func()
  File "C:\Flask\app\__init__.py", line 91, in get_locale
    return request.accept_languages.best_match(app.config['LANGUAGES'])
NameError: name 'app' is not defined
2019-07-24 14:13:30,192 ERROR: Exception on / [GET] [in C:\Flask\venv\lib\site-packages\flask\app.py:1891]
Traceback (most recent call last):
  File "C:\Flask\venv\lib\site-packages\flask\app.py", line 2446, in wsgi_app
    response = self.full_dispatch_request()
  File "C:\Flask\venv\lib\site-packages\flask\app.py", line 1951, in full_dispatch_request
    rv = self.handle_user_exception(e)
  File "C:\Flask\venv\lib\site-packages\flask\app.py", line 1820, in handle_user_exception
    reraise(exc_type, exc_value, tb)
  File "C:\Flask\venv\lib\site-packages\flask\_compat.py", line 39, in reraise
    raise value
  File "C:\Flask\venv\lib\site-packages\flask\app.py", line 1947, in full_dispatch_request
    rv = self.preprocess_request()
  File "C:\Flask\venv\lib\site-packages\flask\app.py", line 2241, in preprocess_request
    rv = func()
  File "C:\Flask\app\main\routes.py", line 17, in before_request
    g.locale = 'zh_CN' if str(get_locale()).startswith('zh') else str(get_locale())
  File "C:\Flask\venv\lib\site-packages\flask_babel\__init__.py", line 257, in get_locale
    rv = babel.locale_selector_func()
  File "C:\Flask\app\__init__.py", line 91, in get_locale
    return request.accept_languages.best_match(app.config['LANGUAGES'])
NameError: name 'app' is not defined
2019-07-24 14:13:39,191 ERROR: Exception on /main/index [GET] [in C:\Flask\venv\lib\site-packages\flask\app.py:1891]
Traceback (most recent call last):
  File "C:\Flask\venv\lib\site-packages\flask\app.py", line 2446, in wsgi_app
    response = self.full_dispatch_request()
  File "C:\Flask\venv\lib\site-packages\flask\app.py", line 1951, in full_dispatch_request
    rv = self.handle_user_exception(e)
  File "C:\Flask\venv\lib\site-packages\flask\app.py", line 1820, in handle_user_exception
    reraise(exc_type, exc_value, tb)
  File "C:\Flask\venv\lib\site-packages\flask\_compat.py", line 39, in reraise
    raise value
  File "C:\Flask\venv\lib\site-packages\flask\app.py", line 1947, in full_dispatch_request
    rv = self.preprocess_request()
  File "C:\Flask\venv\lib\site-packages\flask\app.py", line 2241, in preprocess_request
    rv = func()
  File "C:\Flask\app\main\routes.py", line 17, in before_request
    g.locale = 'zh_CN' if str(get_locale()).startswith('zh') else str(get_locale())
  File "C:\Flask\venv\lib\site-packages\flask_babel\__init__.py", line 257, in get_locale
    rv = babel.locale_selector_func()
  File "C:\Flask\app\__init__.py", line 91, in get_locale
    return request.accept_languages.best_match(app.config['LANGUAGES'])
NameError: name 'app' is not defined
2019-07-24 14:14:17,427 INFO: Microblog startup [in C:\Flask\app\__init__.py:85]
2019-07-24 14:14:19,312 ERROR: Exception on / [GET] [in C:\Flask\venv\lib\site-packages\flask\app.py:1891]
Traceback (most recent call last):
  File "C:\Flask\venv\lib\site-packages\flask\app.py", line 2446, in wsgi_app
    response = self.full_dispatch_request()
  File "C:\Flask\venv\lib\site-packages\flask\app.py", line 1951, in full_dispatch_request
    rv = self.handle_user_exception(e)
  File "C:\Flask\venv\lib\site-packages\flask\app.py", line 1820, in handle_user_exception
    reraise(exc_type, exc_value, tb)
  File "C:\Flask\venv\lib\site-packages\flask\_compat.py", line 39, in reraise
    raise value
  File "C:\Flask\venv\lib\site-packages\flask\app.py", line 1947, in full_dispatch_request
    rv = self.preprocess_request()
  File "C:\Flask\venv\lib\site-packages\flask\app.py", line 2241, in preprocess_request
    rv = func()
  File "C:\Flask\app\main\routes.py", line 17, in before_request
    g.locale = 'zh_CN' if str(get_locale()).startswith('zh') else str(get_locale())
  File "C:\Flask\venv\lib\site-packages\flask_babel\__init__.py", line 257, in get_locale
    rv = babel.locale_selector_func()
  File "C:\Flask\app\__init__.py", line 91, in get_locale
    return request.accept_languages.best_match(Config['LANGUAGES'])
TypeError: 'type' object is not subscriptable
